{
 "cells": [
  {
   "cell_type": "code",
   "execution_count": 55,
   "metadata": {},
   "outputs": [
    {
     "name": "stdout",
     "output_type": "stream",
     "text": [
      "ERROR! Session/line number was not unique in database. History logging moved to new session 136\n"
     ]
    }
   ],
   "source": [
    "import pandas as pd\n",
    "import time\n",
    "import requests\n"
   ]
  },
  {
   "cell_type": "code",
   "execution_count": 9,
   "metadata": {},
   "outputs": [],
   "source": [
    "mathiasAPI = \"AIzaSyCt4jyjtrlCShT2W9cneZUI3SkHQlWF3SI\""
   ]
  },
  {
   "cell_type": "code",
   "execution_count": 7,
   "metadata": {},
   "outputs": [],
   "source": [
    "zone_data = pd.read_csv(\"../../data/zone_coordinates.csv\", index_col = 0)"
   ]
  },
  {
   "cell_type": "code",
   "execution_count": 8,
   "metadata": {},
   "outputs": [
    {
     "data": {
      "text/html": [
       "<div>\n",
       "<style scoped>\n",
       "    .dataframe tbody tr th:only-of-type {\n",
       "        vertical-align: middle;\n",
       "    }\n",
       "\n",
       "    .dataframe tbody tr th {\n",
       "        vertical-align: top;\n",
       "    }\n",
       "\n",
       "    .dataframe thead th {\n",
       "        text-align: right;\n",
       "    }\n",
       "</style>\n",
       "<table border=\"1\" class=\"dataframe\">\n",
       "  <thead>\n",
       "    <tr style=\"text-align: right;\">\n",
       "      <th></th>\n",
       "      <th>Zone</th>\n",
       "      <th>Lower Left</th>\n",
       "      <th>Upper Right</th>\n",
       "      <th>Center</th>\n",
       "    </tr>\n",
       "  </thead>\n",
       "  <tbody>\n",
       "    <tr>\n",
       "      <th>0</th>\n",
       "      <td>1</td>\n",
       "      <td>[10.79377655, 59.96421346153846]</td>\n",
       "      <td>[10.802510575000001, 59.96875023076923]</td>\n",
       "      <td>[10.798143562500002, 59.96648184615385]</td>\n",
       "    </tr>\n",
       "    <tr>\n",
       "      <th>1</th>\n",
       "      <td>2</td>\n",
       "      <td>[10.785042525, 59.96421346153846]</td>\n",
       "      <td>[10.79377655, 59.96875023076923]</td>\n",
       "      <td>[10.7894095375, 59.96648184615385]</td>\n",
       "    </tr>\n",
       "    <tr>\n",
       "      <th>2</th>\n",
       "      <td>3</td>\n",
       "      <td>[10.776308499999999, 59.96421346153846]</td>\n",
       "      <td>[10.785042525, 59.96875023076923]</td>\n",
       "      <td>[10.7806755125, 59.96648184615385]</td>\n",
       "    </tr>\n",
       "    <tr>\n",
       "      <th>3</th>\n",
       "      <td>4</td>\n",
       "      <td>[10.767574475, 59.96421346153846]</td>\n",
       "      <td>[10.7763085, 59.96875023076923]</td>\n",
       "      <td>[10.771941487500001, 59.96648184615385]</td>\n",
       "    </tr>\n",
       "    <tr>\n",
       "      <th>4</th>\n",
       "      <td>5</td>\n",
       "      <td>[10.75884045, 59.96421346153846]</td>\n",
       "      <td>[10.767574475, 59.96875023076923]</td>\n",
       "      <td>[10.763207462499999, 59.96648184615385]</td>\n",
       "    </tr>\n",
       "  </tbody>\n",
       "</table>\n",
       "</div>"
      ],
      "text/plain": [
       "   Zone                               Lower Left  \\\n",
       "0     1         [10.79377655, 59.96421346153846]   \n",
       "1     2        [10.785042525, 59.96421346153846]   \n",
       "2     3  [10.776308499999999, 59.96421346153846]   \n",
       "3     4        [10.767574475, 59.96421346153846]   \n",
       "4     5         [10.75884045, 59.96421346153846]   \n",
       "\n",
       "                               Upper Right  \\\n",
       "0  [10.802510575000001, 59.96875023076923]   \n",
       "1         [10.79377655, 59.96875023076923]   \n",
       "2        [10.785042525, 59.96875023076923]   \n",
       "3          [10.7763085, 59.96875023076923]   \n",
       "4        [10.767574475, 59.96875023076923]   \n",
       "\n",
       "                                    Center  \n",
       "0  [10.798143562500002, 59.96648184615385]  \n",
       "1       [10.7894095375, 59.96648184615385]  \n",
       "2       [10.7806755125, 59.96648184615385]  \n",
       "3  [10.771941487500001, 59.96648184615385]  \n",
       "4  [10.763207462499999, 59.96648184615385]  "
      ]
     },
     "execution_count": 8,
     "metadata": {},
     "output_type": "execute_result"
    }
   ],
   "source": [
    "zone_data.head()"
   ]
  },
  {
   "cell_type": "code",
   "execution_count": 10,
   "metadata": {},
   "outputs": [
    {
     "data": {
      "text/plain": [
       "254"
      ]
     },
     "execution_count": 10,
     "metadata": {},
     "output_type": "execute_result"
    }
   ],
   "source": [
    "len(zone_data)"
   ]
  },
  {
   "cell_type": "code",
   "execution_count": 48,
   "metadata": {},
   "outputs": [],
   "source": [
    "coordinate_string = \"\"\n",
    "for i in range(254):\n",
    "    coordinates_string = str(zone_data.loc[zone_data['Zone'] == i+1, 'Center'])\n",
    "    coordinates_string = coordinates_string.split(\"   \")[1]\n",
    "    coordinates_string = coordinates_string[2:-29]\n",
    "    long, lat = coordinates_string.split(\", \")\n",
    "    coordinate_string += lat + \",\" + long + \"|\"\n",
    "\n",
    "coordinate_string = coordinate_string[:-1]\n",
    "    "
   ]
  },
  {
   "cell_type": "code",
   "execution_count": 49,
   "metadata": {},
   "outputs": [
    {
     "name": "stdout",
     "output_type": "stream",
     "text": [
      "59.96648184615385,10.798143562500002|59.96648184615385,10.7894095375|59.96648184615385,10.7806755125|59.96648184615385,10.771941487500001|59.96648184615385,10.763207462499999|59.96648184615385,10.7544734375|59.96648184615385,10.737005387500002|59.96648184615385,10.7282713625|59.96194507692307,10.798143562500002|59.96194507692307,10.7894095375|59.96194507692307,10.7806755125|59.96194507692307,10.763207462499999|59.96194507692307,10.7544734375|59.96194507692307,10.7457394125|59.96194507692307,10.737005387500002|59.96194507692307,10.7282713625|59.957408307692305,10.798143562500002|59.957408307692305,10.7894095375|59.957408307692305,10.7806755125|59.957408307692305,10.763207462499999|59.957408307692305,10.7544734375|59.957408307692305,10.7457394125|59.957408307692305,10.737005387500002|59.957408307692305,10.7282713625|59.957408307692305,10.7195373375|59.95287153846154,10.798143562500002|59.95287153846154,10.7894095375|59.95287153846154,10.7806755125|59.95287153846154,10.771941487500001|59.95287153846154,10.763207462499999|59.95287153846154,10.7544734375|59.95287153846154,10.7457394125|59.95287153846154,10.737005387500002|59.95287153846154,10.7282713625|59.95287153846154,10.7195373375|59.94833476923077,10.8068775875|59.94833476923077,10.798143562500002|59.94833476923077,10.7894095375|59.94833476923077,10.7806755125|59.94833476923077,10.771941487500001|59.94833476923077,10.763207462499999|59.94833476923077,10.7544734375|59.94833476923077,10.7457394125|59.94833476923077,10.737005387500002|59.94833476923077,10.7282713625|59.94833476923077,10.710803312500001|59.943798,10.8068775875|59.943798,10.798143562500002|59.943798,10.7894095375|59.943798,10.7806755125|59.943798,10.771941487500001|59.943798,10.763207462499999|59.943798,10.7544734375|59.943798,10.7457394125|59.943798,10.737005387500002|59.943798,10.7282713625|59.943798,10.7195373375|59.943798,10.710803312500001|59.943798,10.702069287499999|59.939261230769226,10.894217837500001|59.939261230769226,10.833079662500001|59.939261230769226,10.824345637499999|59.939261230769226,10.8156116125|59.939261230769226,10.8068775875|59.939261230769226,10.798143562500002|59.939261230769226,10.7894095375|59.939261230769226,10.7806755125|59.939261230769226,10.771941487500001|59.939261230769226,10.763207462499999|59.939261230769226,10.7544734375|59.939261230769226,10.7457394125|59.939261230769226,10.737005387500002|59.939261230769226,10.7282713625|59.939261230769226,10.7195373375|59.939261230769226,10.710803312500001|59.939261230769226,10.702069287499999|59.939261230769226,10.6933352625|59.939261230769226,10.6846012375|59.93472446153846,10.8680157625|59.93472446153846,10.833079662500001|59.93472446153846,10.824345637499999|59.93472446153846,10.8156116125|59.93472446153846,10.8068775875|59.93472446153846,10.798143562500002|59.93472446153846,10.7894095375|59.93472446153846,10.7806755125|59.93472446153846,10.771941487500001|59.93472446153846,10.763207462499999|59.93472446153846,10.7544734375|59.93472446153846,10.7457394125|59.93472446153846,10.737005387500002|59.93472446153846,10.7282713625|59.93472446153846,10.7195373375|59.93472446153846,10.710803312500001|59.93472446153846,10.702069287499999|59.93472446153846,10.6933352625|59.93472446153846,10.6846012375|59.93472446153846,10.675867212500002|59.93018769230769,10.833079662500001|59.93018769230769,10.8156116125|59.93018769230769,10.8068775875|59.93018769230769,10.798143562500002|59.93018769230769,10.7894095375|59.93018769230769,10.7806755125|59.93018769230769,10.771941487500001|59.93018769230769,10.763207462499999|59.93018769230769,10.7544734375|59.93018769230769,10.7457394125|59.93018769230769,10.737005387500002|59.93018769230769,10.7282713625|59.93018769230769,10.7195373375|59.93018769230769,10.710803312500001|59.93018769230769,10.702069287499999|59.93018769230769,10.6933352625|59.93018769230769,10.6846012375|59.93018769230769,10.675867212500002|59.93018769230769,10.6671331875|59.93018769230769,10.6583991625|59.92565092307692,10.824345637499999|59.92565092307692,10.8068775875|59.92565092307692,10.798143562500002|59.92565092307692,10.7894095375|59.92565092307692,10.7806755125|59.92565092307692,10.771941487500001|59.92565092307692,10.763207462499999|59.92565092307692,10.7544734375|59.92565092307692,10.7457394125|59.92565092307692,10.737005387500002|59.92565092307692,10.7282713625|59.92565092307692,10.7195373375|59.92565092307692,10.710803312500001|59.92565092307692,10.6933352625|59.92565092307692,10.6846012375|59.92565092307692,10.675867212500002|59.92565092307692,10.6671331875|59.92565092307692,10.6583991625|59.92565092307692,10.649665137500001|59.921114153846155,10.824345637499999|59.921114153846155,10.8156116125|59.921114153846155,10.8068775875|59.921114153846155,10.798143562500002|59.921114153846155,10.7894095375|59.921114153846155,10.7806755125|59.921114153846155,10.771941487500001|59.921114153846155,10.763207462499999|59.921114153846155,10.7544734375|59.921114153846155,10.7457394125|59.921114153846155,10.737005387500002|59.921114153846155,10.7282713625|59.921114153846155,10.7195373375|59.921114153846155,10.710803312500001|59.921114153846155,10.702069287499999|59.921114153846155,10.6933352625|59.921114153846155,10.6846012375|59.921114153846155,10.675867212500002|59.921114153846155,10.6671331875|59.921114153846155,10.6583991625|59.921114153846155,10.649665137500001|59.921114153846155,10.640931112499999|59.921114153846155,10.6321970875|59.91657738461538,10.824345637499999|59.91657738461538,10.8156116125|59.91657738461538,10.8068775875|59.91657738461538,10.798143562500002|59.91657738461538,10.7894095375|59.91657738461538,10.7806755125|59.91657738461538,10.771941487500001|59.91657738461538,10.763207462499999|59.91657738461538,10.7544734375|59.91657738461538,10.7457394125|59.91657738461538,10.737005387500002|59.91657738461538,10.7195373375|59.91657738461538,10.710803312500001|59.91657738461538,10.702069287499999|59.91657738461538,10.6933352625|59.91657738461538,10.6671331875|59.91657738461538,10.6583991625|59.91657738461538,10.649665137500001|59.91657738461538,10.640931112499999|59.91657738461538,10.6321970875|59.91204061538461,10.8156116125|59.91204061538461,10.8068775875|59.91204061538461,10.798143562500002|59.91204061538461,10.7894095375|59.91204061538461,10.7806755125|59.91204061538461,10.771941487500001|59.91204061538461,10.763207462499999|59.91204061538461,10.7544734375|59.91204061538461,10.7457394125|59.91204061538461,10.7282713625|59.91204061538461,10.7195373375|59.91204061538461,10.710803312500001|59.91204061538461,10.702069287499999|59.91204061538461,10.640931112499999|59.91204061538461,10.6321970875|59.907503846153844,10.8156116125|59.907503846153844,10.8068775875|59.907503846153844,10.798143562500002|59.907503846153844,10.7894095375|59.907503846153844,10.7806755125|59.907503846153844,10.771941487500001|59.907503846153844,10.763207462499999|59.907503846153844,10.7457394125|59.907503846153844,10.6234630625|59.902967076923076,10.8068775875|59.902967076923076,10.798143562500002|59.902967076923076,10.7894095375|59.902967076923076,10.7806755125|59.902967076923076,10.771941487500001|59.902967076923076,10.763207462499999|59.902967076923076,10.6234630625|59.89843030769231,10.8156116125|59.89843030769231,10.8068775875|59.89843030769231,10.798143562500002|59.89843030769231,10.7894095375|59.89843030769231,10.7806755125|59.89843030769231,10.6321970875|59.89843030769231,10.6234630625|59.89389353846154,10.824345637499999|59.89389353846154,10.8156116125|59.89389353846154,10.8068775875|59.89389353846154,10.798143562500002|59.89389353846154,10.7894095375|59.89389353846154,10.7806755125|59.89389353846154,10.6321970875|59.889356769230766,10.798143562500002|59.889356769230766,10.7806755125|59.889356769230766,10.771941487500001|59.88482,10.8068775875|59.88482,10.798143562500002|59.88482,10.7894095375|59.88482,10.7806755125|59.88028323076923,10.824345637499999|59.88028323076923,10.8068775875|59.88028323076923,10.798143562500002|59.88028323076923,10.7894095375|59.88028323076923,10.7806755125|59.87574646153846,10.824345637499999|59.87574646153846,10.8156116125|59.87574646153846,10.8068775875|59.87574646153846,10.798143562500002|59.87574646153846,10.7894095375|59.87574646153846,10.7806755125|59.871209692307694,10.824345637499999|59.871209692307694,10.8156116125|59.871209692307694,10.8068775875|59.871209692307694,10.7894095375|59.86667292307692,10.824345637499999|59.86667292307692,10.8156116125|59.86667292307692,10.8068775875|59.86667292307692,10.798143562500002|59.86213615384615,10.8156116125|59.86213615384615,10.8068775875|59.86213615384615,10.798143562500002\n"
     ]
    }
   ],
   "source": [
    "print(coordinate_string)"
   ]
  },
  {
   "cell_type": "code",
   "execution_count": null,
   "metadata": {},
   "outputs": [
    {
     "name": "stdout",
     "output_type": "stream",
     "text": [
      "ERROR! Session/line number was not unique in database. History logging moved to new session 137\n"
     ]
    },
    {
     "name": "stderr",
     "output_type": "stream",
     "text": [
      "ERROR:root:Internal Python error in the inspect module.\n",
      "Below is the traceback from this internal error.\n",
      "\n",
      "ERROR:root:Internal Python error in the inspect module.\n",
      "Below is the traceback from this internal error.\n",
      "\n",
      "ERROR:root:Internal Python error in the inspect module.\n",
      "Below is the traceback from this internal error.\n",
      "\n"
     ]
    },
    {
     "name": "stdout",
     "output_type": "stream",
     "text": [
      "Traceback (most recent call last):\n",
      "  File \"/Applications/anaconda3/lib/python3.8/site-packages/IPython/core/interactiveshell.py\", line 3418, in run_code\n",
      "    exec(code_obj, self.user_global_ns, self.user_ns)\n",
      "  File \"<ipython-input-56-50606840163d>\", line 3, in <module>\n",
      "    seconds = data[\"rows\"][0][\"elements\"][0][\"duration\"][\"value\"]\n",
      "TypeError: 'method' object is not subscriptable\n",
      "\n",
      "During handling of the above exception, another exception occurred:\n",
      "\n",
      "Traceback (most recent call last):\n",
      "  File \"/Applications/anaconda3/lib/python3.8/site-packages/IPython/core/interactiveshell.py\", line 2045, in showtraceback\n",
      "    stb = value._render_traceback_()\n",
      "AttributeError: 'TypeError' object has no attribute '_render_traceback_'\n",
      "\n",
      "During handling of the above exception, another exception occurred:\n",
      "\n",
      "Traceback (most recent call last):\n",
      "  File \"/Applications/anaconda3/lib/python3.8/site-packages/IPython/core/ultratb.py\", line 1170, in get_records\n",
      "    return _fixed_getinnerframes(etb, number_of_lines_of_context, tb_offset)\n",
      "  File \"/Applications/anaconda3/lib/python3.8/site-packages/IPython/core/ultratb.py\", line 316, in wrapped\n",
      "    return f(*args, **kwargs)\n",
      "  File \"/Applications/anaconda3/lib/python3.8/site-packages/IPython/core/ultratb.py\", line 350, in _fixed_getinnerframes\n",
      "    records = fix_frame_records_filenames(inspect.getinnerframes(etb, context))\n",
      "  File \"/Applications/anaconda3/lib/python3.8/inspect.py\", line 1503, in getinnerframes\n",
      "    frameinfo = (tb.tb_frame,) + getframeinfo(tb, context)\n",
      "  File \"/Applications/anaconda3/lib/python3.8/inspect.py\", line 1461, in getframeinfo\n",
      "    filename = getsourcefile(frame) or getfile(frame)\n",
      "  File \"/Applications/anaconda3/lib/python3.8/inspect.py\", line 708, in getsourcefile\n",
      "    if getattr(getmodule(object, filename), '__loader__', None) is not None:\n",
      "  File \"/Applications/anaconda3/lib/python3.8/inspect.py\", line 737, in getmodule\n",
      "    file = getabsfile(object, _filename)\n",
      "  File \"/Applications/anaconda3/lib/python3.8/inspect.py\", line 721, in getabsfile\n",
      "    return os.path.normcase(os.path.abspath(_filename))\n",
      "  File \"/Applications/anaconda3/lib/python3.8/posixpath.py\", line 379, in abspath\n",
      "    cwd = os.getcwd()\n",
      "FileNotFoundError: [Errno 2] No such file or directory\n",
      "Traceback (most recent call last):\n",
      "  File \"/Applications/anaconda3/lib/python3.8/site-packages/IPython/core/interactiveshell.py\", line 3418, in run_code\n",
      "    exec(code_obj, self.user_global_ns, self.user_ns)\n",
      "  File \"<ipython-input-56-50606840163d>\", line 3, in <module>\n",
      "    seconds = data[\"rows\"][0][\"elements\"][0][\"duration\"][\"value\"]\n",
      "TypeError: 'method' object is not subscriptable\n",
      "\n",
      "During handling of the above exception, another exception occurred:\n",
      "\n",
      "Traceback (most recent call last):\n",
      "  File \"/Applications/anaconda3/lib/python3.8/site-packages/IPython/core/interactiveshell.py\", line 2045, in showtraceback\n",
      "    stb = value._render_traceback_()\n",
      "AttributeError: 'TypeError' object has no attribute '_render_traceback_'\n",
      "\n",
      "During handling of the above exception, another exception occurred:\n",
      "\n",
      "Traceback (most recent call last):\n",
      "  File \"/Applications/anaconda3/lib/python3.8/site-packages/IPython/core/interactiveshell.py\", line 3338, in run_ast_nodes\n",
      "    if (await self.run_code(code, result,  async_=asy)):\n",
      "  File \"/Applications/anaconda3/lib/python3.8/site-packages/IPython/core/interactiveshell.py\", line 3435, in run_code\n",
      "    self.showtraceback(running_compiled_code=True)\n",
      "  File \"/Applications/anaconda3/lib/python3.8/site-packages/IPython/core/interactiveshell.py\", line 2047, in showtraceback\n",
      "    stb = self.InteractiveTB.structured_traceback(etype,\n",
      "  File \"/Applications/anaconda3/lib/python3.8/site-packages/IPython/core/ultratb.py\", line 1436, in structured_traceback\n",
      "    return FormattedTB.structured_traceback(\n",
      "  File \"/Applications/anaconda3/lib/python3.8/site-packages/IPython/core/ultratb.py\", line 1336, in structured_traceback\n",
      "    return VerboseTB.structured_traceback(\n",
      "  File \"/Applications/anaconda3/lib/python3.8/site-packages/IPython/core/ultratb.py\", line 1193, in structured_traceback\n",
      "    formatted_exception = self.format_exception_as_a_whole(etype, evalue, etb, number_of_lines_of_context,\n",
      "  File \"/Applications/anaconda3/lib/python3.8/site-packages/IPython/core/ultratb.py\", line 1151, in format_exception_as_a_whole\n",
      "    last_unique, recursion_repeat = find_recursion(orig_etype, evalue, records)\n",
      "  File \"/Applications/anaconda3/lib/python3.8/site-packages/IPython/core/ultratb.py\", line 451, in find_recursion\n",
      "    return len(records), 0\n",
      "TypeError: object of type 'NoneType' has no len()\n",
      "\n",
      "During handling of the above exception, another exception occurred:\n",
      "\n",
      "Traceback (most recent call last):\n",
      "  File \"/Applications/anaconda3/lib/python3.8/site-packages/IPython/core/interactiveshell.py\", line 2045, in showtraceback\n",
      "    stb = value._render_traceback_()\n",
      "AttributeError: 'TypeError' object has no attribute '_render_traceback_'\n",
      "\n",
      "During handling of the above exception, another exception occurred:\n",
      "\n",
      "Traceback (most recent call last):\n",
      "  File \"/Applications/anaconda3/lib/python3.8/site-packages/IPython/core/ultratb.py\", line 1170, in get_records\n",
      "    return _fixed_getinnerframes(etb, number_of_lines_of_context, tb_offset)\n",
      "  File \"/Applications/anaconda3/lib/python3.8/site-packages/IPython/core/ultratb.py\", line 316, in wrapped\n",
      "    return f(*args, **kwargs)\n",
      "  File \"/Applications/anaconda3/lib/python3.8/site-packages/IPython/core/ultratb.py\", line 350, in _fixed_getinnerframes\n",
      "    records = fix_frame_records_filenames(inspect.getinnerframes(etb, context))\n",
      "  File \"/Applications/anaconda3/lib/python3.8/inspect.py\", line 1503, in getinnerframes\n",
      "    frameinfo = (tb.tb_frame,) + getframeinfo(tb, context)\n",
      "  File \"/Applications/anaconda3/lib/python3.8/inspect.py\", line 1461, in getframeinfo\n",
      "    filename = getsourcefile(frame) or getfile(frame)\n",
      "  File \"/Applications/anaconda3/lib/python3.8/inspect.py\", line 708, in getsourcefile\n",
      "    if getattr(getmodule(object, filename), '__loader__', None) is not None:\n",
      "  File \"/Applications/anaconda3/lib/python3.8/inspect.py\", line 737, in getmodule\n",
      "    file = getabsfile(object, _filename)\n",
      "  File \"/Applications/anaconda3/lib/python3.8/inspect.py\", line 721, in getabsfile\n",
      "    return os.path.normcase(os.path.abspath(_filename))\n",
      "  File \"/Applications/anaconda3/lib/python3.8/posixpath.py\", line 379, in abspath\n",
      "    cwd = os.getcwd()\n",
      "FileNotFoundError: [Errno 2] No such file or directory\n",
      "Traceback (most recent call last):\n",
      "  File \"/Applications/anaconda3/lib/python3.8/site-packages/IPython/core/interactiveshell.py\", line 3418, in run_code\n",
      "    exec(code_obj, self.user_global_ns, self.user_ns)\n",
      "  File \"<ipython-input-56-50606840163d>\", line 3, in <module>\n",
      "    seconds = data[\"rows\"][0][\"elements\"][0][\"duration\"][\"value\"]\n",
      "TypeError: 'method' object is not subscriptable\n",
      "\n",
      "During handling of the above exception, another exception occurred:\n",
      "\n",
      "Traceback (most recent call last):\n",
      "  File \"/Applications/anaconda3/lib/python3.8/site-packages/IPython/core/interactiveshell.py\", line 2045, in showtraceback\n",
      "    stb = value._render_traceback_()\n",
      "AttributeError: 'TypeError' object has no attribute '_render_traceback_'\n",
      "\n",
      "During handling of the above exception, another exception occurred:\n",
      "\n",
      "Traceback (most recent call last):\n",
      "  File \"/Applications/anaconda3/lib/python3.8/site-packages/IPython/core/interactiveshell.py\", line 3338, in run_ast_nodes\n",
      "    if (await self.run_code(code, result,  async_=asy)):\n",
      "  File \"/Applications/anaconda3/lib/python3.8/site-packages/IPython/core/interactiveshell.py\", line 3435, in run_code\n",
      "    self.showtraceback(running_compiled_code=True)\n",
      "  File \"/Applications/anaconda3/lib/python3.8/site-packages/IPython/core/interactiveshell.py\", line 2047, in showtraceback\n",
      "    stb = self.InteractiveTB.structured_traceback(etype,\n",
      "  File \"/Applications/anaconda3/lib/python3.8/site-packages/IPython/core/ultratb.py\", line 1436, in structured_traceback\n",
      "    return FormattedTB.structured_traceback(\n",
      "  File \"/Applications/anaconda3/lib/python3.8/site-packages/IPython/core/ultratb.py\", line 1336, in structured_traceback\n",
      "    return VerboseTB.structured_traceback(\n",
      "  File \"/Applications/anaconda3/lib/python3.8/site-packages/IPython/core/ultratb.py\", line 1193, in structured_traceback\n",
      "    formatted_exception = self.format_exception_as_a_whole(etype, evalue, etb, number_of_lines_of_context,\n",
      "  File \"/Applications/anaconda3/lib/python3.8/site-packages/IPython/core/ultratb.py\", line 1151, in format_exception_as_a_whole\n",
      "    last_unique, recursion_repeat = find_recursion(orig_etype, evalue, records)\n",
      "  File \"/Applications/anaconda3/lib/python3.8/site-packages/IPython/core/ultratb.py\", line 451, in find_recursion\n",
      "    return len(records), 0\n",
      "TypeError: object of type 'NoneType' has no len()\n",
      "\n",
      "During handling of the above exception, another exception occurred:\n",
      "\n",
      "Traceback (most recent call last):\n",
      "  File \"/Applications/anaconda3/lib/python3.8/site-packages/IPython/core/interactiveshell.py\", line 2045, in showtraceback\n",
      "    stb = value._render_traceback_()\n",
      "AttributeError: 'TypeError' object has no attribute '_render_traceback_'\n",
      "\n",
      "During handling of the above exception, another exception occurred:\n",
      "\n",
      "Traceback (most recent call last):\n",
      "  File \"/Applications/anaconda3/lib/python3.8/site-packages/IPython/core/interactiveshell.py\", line 2923, in _run_cell\n",
      "    return runner(coro)\n",
      "  File \"/Applications/anaconda3/lib/python3.8/site-packages/IPython/core/async_helpers.py\", line 68, in _pseudo_sync_runner\n",
      "    coro.send(None)\n",
      "  File \"/Applications/anaconda3/lib/python3.8/site-packages/IPython/core/interactiveshell.py\", line 3146, in run_cell_async\n",
      "    has_raised = await self.run_ast_nodes(code_ast.body, cell_name,\n",
      "  File \"/Applications/anaconda3/lib/python3.8/site-packages/IPython/core/interactiveshell.py\", line 3357, in run_ast_nodes\n",
      "    self.showtraceback()\n",
      "  File \"/Applications/anaconda3/lib/python3.8/site-packages/IPython/core/interactiveshell.py\", line 2047, in showtraceback\n",
      "    stb = self.InteractiveTB.structured_traceback(etype,\n",
      "  File \"/Applications/anaconda3/lib/python3.8/site-packages/IPython/core/ultratb.py\", line 1436, in structured_traceback\n",
      "    return FormattedTB.structured_traceback(\n",
      "  File \"/Applications/anaconda3/lib/python3.8/site-packages/IPython/core/ultratb.py\", line 1336, in structured_traceback\n",
      "    return VerboseTB.structured_traceback(\n",
      "  File \"/Applications/anaconda3/lib/python3.8/site-packages/IPython/core/ultratb.py\", line 1211, in structured_traceback\n",
      "    formatted_exceptions += self.format_exception_as_a_whole(etype, evalue, etb, lines_of_context,\n",
      "  File \"/Applications/anaconda3/lib/python3.8/site-packages/IPython/core/ultratb.py\", line 1151, in format_exception_as_a_whole\n",
      "    last_unique, recursion_repeat = find_recursion(orig_etype, evalue, records)\n",
      "  File \"/Applications/anaconda3/lib/python3.8/site-packages/IPython/core/ultratb.py\", line 451, in find_recursion\n",
      "    return len(records), 0\n",
      "TypeError: object of type 'NoneType' has no len()\n",
      "\n",
      "During handling of the above exception, another exception occurred:\n",
      "\n",
      "Traceback (most recent call last):\n",
      "  File \"/Applications/anaconda3/lib/python3.8/site-packages/IPython/core/interactiveshell.py\", line 2045, in showtraceback\n",
      "    stb = value._render_traceback_()\n",
      "AttributeError: 'TypeError' object has no attribute '_render_traceback_'\n",
      "\n",
      "During handling of the above exception, another exception occurred:\n",
      "\n",
      "Traceback (most recent call last):\n",
      "  File \"/Applications/anaconda3/lib/python3.8/site-packages/IPython/core/ultratb.py\", line 1170, in get_records\n",
      "    return _fixed_getinnerframes(etb, number_of_lines_of_context, tb_offset)\n",
      "  File \"/Applications/anaconda3/lib/python3.8/site-packages/IPython/core/ultratb.py\", line 316, in wrapped\n",
      "    return f(*args, **kwargs)\n",
      "  File \"/Applications/anaconda3/lib/python3.8/site-packages/IPython/core/ultratb.py\", line 350, in _fixed_getinnerframes\n",
      "    records = fix_frame_records_filenames(inspect.getinnerframes(etb, context))\n",
      "  File \"/Applications/anaconda3/lib/python3.8/inspect.py\", line 1503, in getinnerframes\n",
      "    frameinfo = (tb.tb_frame,) + getframeinfo(tb, context)\n",
      "  File \"/Applications/anaconda3/lib/python3.8/inspect.py\", line 1461, in getframeinfo\n",
      "    filename = getsourcefile(frame) or getfile(frame)\n",
      "  File \"/Applications/anaconda3/lib/python3.8/inspect.py\", line 708, in getsourcefile\n",
      "    if getattr(getmodule(object, filename), '__loader__', None) is not None:\n",
      "  File \"/Applications/anaconda3/lib/python3.8/inspect.py\", line 737, in getmodule\n",
      "    file = getabsfile(object, _filename)\n",
      "  File \"/Applications/anaconda3/lib/python3.8/inspect.py\", line 721, in getabsfile\n",
      "    return os.path.normcase(os.path.abspath(_filename))\n",
      "  File \"/Applications/anaconda3/lib/python3.8/posixpath.py\", line 379, in abspath\n",
      "    cwd = os.getcwd()\n",
      "FileNotFoundError: [Errno 2] No such file or directory\n"
     ]
    }
   ],
   "source": [
    "url = \"https://maps.googleapis.com/maps/api/distancematrix/json?origins=\" + \"59.96648184615385,10.798143562500002|59.96648184615385,10.7894095375\" + \"&destinations=\" + \"59.96648184615385,10.798143562500002|59.96648184615385,10.7894095375\" + \"&key=\" + mathiasAPI + \"&mode=\" + \"driving\"\n",
    "data = requests.get(url).json\n",
    "seconds = data[\"rows\"][0][\"elements\"][0][\"duration\"][\"value\"]"
   ]
  },
  {
   "cell_type": "code",
   "execution_count": 54,
   "metadata": {},
   "outputs": [
    {
     "name": "stdout",
     "output_type": "stream",
     "text": [
      "<bound method Response.json of <Response [200]>>\n"
     ]
    }
   ],
   "source": [
    "print(data)"
   ]
  },
  {
   "cell_type": "code",
   "execution_count": null,
   "metadata": {},
   "outputs": [],
   "source": [
    "matrix = [[0 for i in range(254)] for j in range(254)]"
   ]
  },
  {
   "cell_type": "code",
   "execution_count": 59,
   "metadata": {},
   "outputs": [
    {
     "name": "stdout",
     "output_type": "stream",
     "text": [
      "ERROR! Session/line number was not unique in database. History logging moved to new session 141\n"
     ]
    }
   ],
   "source": [
    "def cleanCalculateTravelTimeMatrixFromCoordVector(coordVector, transportType, apikey, writeToFile):\n",
    "\tnumberOfCoordinates = len(coordVector)\n",
    "\tsecondMatrix = [[0 for i in range(numberOfCoordinates)] for j in range(numberOfCoordinates)]\n",
    "\tnumberOfQueries = 0\n",
    "\ttotalQueries = 0\n",
    "\tfor i in range(numberOfCoordinates):\n",
    "\t\torigin = makeStringListFromCoordinateVector([coordVector[i]])\n",
    "\t\tfor j in range(numberOfCoordinates):\n",
    "\t\t\tif(numberOfQueries > 99):\n",
    "\t\t\t\ttime.sleep(1)\n",
    "\t\t\t\tnumberOfQueries = 0\n",
    "\t\t\tdestination = makeStringListFromCoordinateVector([coordVector[j]])\n",
    "\t\t\turl = \"https://maps.googleapis.com/maps/api/distancematrix/json?origins=\" + origin + \"&destinations=\" + destination + \"&key=\" + apikey + \"&mode=\" + transportType\n",
    "\t\t\tdata = requests.get(url).json()\n",
    "\t\t\t#print(data)\n",
    "\t\t\tif (\"error_message\" in data.keys()):\n",
    "\t\t\t\tprint(data[\"error_message\"])\n",
    "\t\t\t\treturn secondMatrix\n",
    "\t\t\t# retrieve travel time in seconds from json object\n",
    "\t\t\tseconds = data[\"rows\"][0][\"elements\"][0][\"duration\"][\"value\"]\n",
    "\t\t\t# add travel time to matrix\n",
    "\t\t\tsecondMatrix[i][j] = seconds\n",
    "\t\t\tnumberOfQueries += 1\n",
    "\t\t\ttotalQueries += 1\n",
    "\t\t\t#print(totalQueries)\n",
    "\tif(writeToFile):\n",
    "\t\twriteMatrixToFile(secondMatrix, transportType)\n",
    "\t\tprint(secondMatrix)\n",
    "\n",
    "\treturn secondMatrix\n",
    "\n",
    "def writeMatrixToFile(matrix, transportType):\n",
    "    if transportType == \"\":\n",
    "        transportType = \"car\"\n",
    "    fil = open(\"travelTimes_\" + transportType + \".txt\", \"w\")\n",
    "    writeString = \"\"\n",
    "    for row in matrix:\n",
    "        for elem in row:\n",
    "            writeString += str(elem) + \" \"\n",
    "        writeString = writeString[:-1] + \"\\n\"\n",
    "    fil.write(writeString[:-1])\n",
    "    fil.close()\n",
    "\n",
    "\n",
    "def makeStringListFromCoordinateVector(coordVector):\n",
    "    ret = \"\"\n",
    "    for coor in coordVector:\n",
    "        ret += str(coor[0]) + \",\" + str(coor[1]) + \"|\"\n",
    "    ret = ret[:-1]\n",
    "    return ret\n",
    "\n",
    "\n",
    "def run(coordVector, transportType, writeToFile):\n",
    "    apikey = LARSAPIKEY_1\n",
    "    #print(\"number of coordinates\", len(coordVector))\n",
    "    return cleanCalculateTravelTimeMatrixFromCoordVector(coordVector, transportType, apikey, writeToFile)"
   ]
  },
  {
   "cell_type": "code",
   "execution_count": 57,
   "metadata": {},
   "outputs": [
    {
     "name": "stdout",
     "output_type": "stream",
     "text": [
      "ERROR! Session/line number was not unique in database. History logging moved to new session 140\n"
     ]
    }
   ],
   "source": [
    "coordvector =[]\n",
    "coords = coordinate_string.split(\"|\")\n",
    "for i in range(254):\n",
    "    coordinates = coords[i].split(\",\")\n",
    "    coordinates[0] = float(coordinates[0])\n",
    "    coordinates[1] = float(coordinates[1])\n",
    "    coordvector.append(coordinates)"
   ]
  },
  {
   "cell_type": "code",
   "execution_count": null,
   "metadata": {
    "scrolled": false
   },
   "outputs": [
    {
     "name": "stderr",
     "output_type": "stream",
     "text": [
      "ERROR:root:Internal Python error in the inspect module.\n",
      "Below is the traceback from this internal error.\n",
      "\n",
      "ERROR:root:Internal Python error in the inspect module.\n",
      "Below is the traceback from this internal error.\n",
      "\n",
      "ERROR:root:Internal Python error in the inspect module.\n",
      "Below is the traceback from this internal error.\n",
      "\n"
     ]
    },
    {
     "name": "stdout",
     "output_type": "stream",
     "text": [
      "Traceback (most recent call last):\n",
      "  File \"/Applications/anaconda3/lib/python3.8/site-packages/IPython/core/interactiveshell.py\", line 3418, in run_code\n",
      "    exec(code_obj, self.user_global_ns, self.user_ns)\n",
      "  File \"<ipython-input-60-02dd82b79a8f>\", line 1, in <module>\n",
      "    car_matrix = cleanCalculateTravelTimeMatrixFromCoordVector(coordvector, \"driving\", mathiasAPI, False)\n",
      "  File \"<ipython-input-59-b25788eaccee>\", line 14, in cleanCalculateTravelTimeMatrixFromCoordVector\n",
      "    data = requests.get(url).json()\n",
      "  File \"/Applications/anaconda3/lib/python3.8/site-packages/requests/api.py\", line 76, in get\n",
      "    return request('get', url, params=params, **kwargs)\n",
      "  File \"/Applications/anaconda3/lib/python3.8/site-packages/requests/api.py\", line 61, in request\n",
      "    return session.request(method=method, url=url, **kwargs)\n",
      "  File \"/Applications/anaconda3/lib/python3.8/site-packages/requests/sessions.py\", line 530, in request\n",
      "    resp = self.send(prep, **send_kwargs)\n",
      "  File \"/Applications/anaconda3/lib/python3.8/site-packages/requests/sessions.py\", line 643, in send\n",
      "    r = adapter.send(request, **kwargs)\n",
      "  File \"/Applications/anaconda3/lib/python3.8/site-packages/requests/adapters.py\", line 439, in send\n",
      "    resp = conn.urlopen(\n",
      "  File \"/Applications/anaconda3/lib/python3.8/site-packages/urllib3/connectionpool.py\", line 670, in urlopen\n",
      "    httplib_response = self._make_request(\n",
      "  File \"/Applications/anaconda3/lib/python3.8/site-packages/urllib3/connectionpool.py\", line 426, in _make_request\n",
      "    six.raise_from(e, None)\n",
      "  File \"<string>\", line 3, in raise_from\n",
      "  File \"/Applications/anaconda3/lib/python3.8/site-packages/urllib3/connectionpool.py\", line 421, in _make_request\n",
      "    httplib_response = conn.getresponse()\n",
      "  File \"/Applications/anaconda3/lib/python3.8/http/client.py\", line 1347, in getresponse\n",
      "    response.begin()\n",
      "  File \"/Applications/anaconda3/lib/python3.8/http/client.py\", line 307, in begin\n",
      "    version, status, reason = self._read_status()\n",
      "  File \"/Applications/anaconda3/lib/python3.8/http/client.py\", line 268, in _read_status\n",
      "    line = str(self.fp.readline(_MAXLINE + 1), \"iso-8859-1\")\n",
      "  File \"/Applications/anaconda3/lib/python3.8/socket.py\", line 669, in readinto\n",
      "    return self._sock.recv_into(b)\n",
      "  File \"/Applications/anaconda3/lib/python3.8/ssl.py\", line 1241, in recv_into\n",
      "    return self.read(nbytes, buffer)\n",
      "  File \"/Applications/anaconda3/lib/python3.8/ssl.py\", line 1099, in read\n",
      "    return self._sslobj.read(len, buffer)\n",
      "KeyboardInterrupt\n",
      "\n",
      "During handling of the above exception, another exception occurred:\n",
      "\n",
      "Traceback (most recent call last):\n",
      "  File \"/Applications/anaconda3/lib/python3.8/site-packages/IPython/core/interactiveshell.py\", line 2045, in showtraceback\n",
      "    stb = value._render_traceback_()\n",
      "AttributeError: 'KeyboardInterrupt' object has no attribute '_render_traceback_'\n",
      "\n",
      "During handling of the above exception, another exception occurred:\n",
      "\n",
      "Traceback (most recent call last):\n",
      "  File \"/Applications/anaconda3/lib/python3.8/site-packages/IPython/core/ultratb.py\", line 1170, in get_records\n",
      "    return _fixed_getinnerframes(etb, number_of_lines_of_context, tb_offset)\n",
      "  File \"/Applications/anaconda3/lib/python3.8/site-packages/IPython/core/ultratb.py\", line 316, in wrapped\n",
      "    return f(*args, **kwargs)\n",
      "  File \"/Applications/anaconda3/lib/python3.8/site-packages/IPython/core/ultratb.py\", line 350, in _fixed_getinnerframes\n",
      "    records = fix_frame_records_filenames(inspect.getinnerframes(etb, context))\n",
      "  File \"/Applications/anaconda3/lib/python3.8/inspect.py\", line 1503, in getinnerframes\n",
      "    frameinfo = (tb.tb_frame,) + getframeinfo(tb, context)\n",
      "  File \"/Applications/anaconda3/lib/python3.8/inspect.py\", line 1461, in getframeinfo\n",
      "    filename = getsourcefile(frame) or getfile(frame)\n",
      "  File \"/Applications/anaconda3/lib/python3.8/inspect.py\", line 708, in getsourcefile\n",
      "    if getattr(getmodule(object, filename), '__loader__', None) is not None:\n",
      "  File \"/Applications/anaconda3/lib/python3.8/inspect.py\", line 737, in getmodule\n",
      "    file = getabsfile(object, _filename)\n",
      "  File \"/Applications/anaconda3/lib/python3.8/inspect.py\", line 721, in getabsfile\n",
      "    return os.path.normcase(os.path.abspath(_filename))\n",
      "  File \"/Applications/anaconda3/lib/python3.8/posixpath.py\", line 379, in abspath\n",
      "    cwd = os.getcwd()\n",
      "FileNotFoundError: [Errno 2] No such file or directory\n",
      "Traceback (most recent call last):\n",
      "  File \"/Applications/anaconda3/lib/python3.8/site-packages/IPython/core/interactiveshell.py\", line 3418, in run_code\n",
      "    exec(code_obj, self.user_global_ns, self.user_ns)\n",
      "  File \"<ipython-input-60-02dd82b79a8f>\", line 1, in <module>\n",
      "    car_matrix = cleanCalculateTravelTimeMatrixFromCoordVector(coordvector, \"driving\", mathiasAPI, False)\n",
      "  File \"<ipython-input-59-b25788eaccee>\", line 14, in cleanCalculateTravelTimeMatrixFromCoordVector\n",
      "    data = requests.get(url).json()\n",
      "  File \"/Applications/anaconda3/lib/python3.8/site-packages/requests/api.py\", line 76, in get\n",
      "    return request('get', url, params=params, **kwargs)\n",
      "  File \"/Applications/anaconda3/lib/python3.8/site-packages/requests/api.py\", line 61, in request\n",
      "    return session.request(method=method, url=url, **kwargs)\n",
      "  File \"/Applications/anaconda3/lib/python3.8/site-packages/requests/sessions.py\", line 530, in request\n",
      "    resp = self.send(prep, **send_kwargs)\n",
      "  File \"/Applications/anaconda3/lib/python3.8/site-packages/requests/sessions.py\", line 643, in send\n",
      "    r = adapter.send(request, **kwargs)\n",
      "  File \"/Applications/anaconda3/lib/python3.8/site-packages/requests/adapters.py\", line 439, in send\n",
      "    resp = conn.urlopen(\n",
      "  File \"/Applications/anaconda3/lib/python3.8/site-packages/urllib3/connectionpool.py\", line 670, in urlopen\n",
      "    httplib_response = self._make_request(\n",
      "  File \"/Applications/anaconda3/lib/python3.8/site-packages/urllib3/connectionpool.py\", line 426, in _make_request\n",
      "    six.raise_from(e, None)\n",
      "  File \"<string>\", line 3, in raise_from\n",
      "  File \"/Applications/anaconda3/lib/python3.8/site-packages/urllib3/connectionpool.py\", line 421, in _make_request\n",
      "    httplib_response = conn.getresponse()\n",
      "  File \"/Applications/anaconda3/lib/python3.8/http/client.py\", line 1347, in getresponse\n",
      "    response.begin()\n",
      "  File \"/Applications/anaconda3/lib/python3.8/http/client.py\", line 307, in begin\n",
      "    version, status, reason = self._read_status()\n",
      "  File \"/Applications/anaconda3/lib/python3.8/http/client.py\", line 268, in _read_status\n",
      "    line = str(self.fp.readline(_MAXLINE + 1), \"iso-8859-1\")\n",
      "  File \"/Applications/anaconda3/lib/python3.8/socket.py\", line 669, in readinto\n",
      "    return self._sock.recv_into(b)\n",
      "  File \"/Applications/anaconda3/lib/python3.8/ssl.py\", line 1241, in recv_into\n",
      "    return self.read(nbytes, buffer)\n",
      "  File \"/Applications/anaconda3/lib/python3.8/ssl.py\", line 1099, in read\n",
      "    return self._sslobj.read(len, buffer)\n",
      "KeyboardInterrupt\n",
      "\n",
      "During handling of the above exception, another exception occurred:\n",
      "\n",
      "Traceback (most recent call last):\n",
      "  File \"/Applications/anaconda3/lib/python3.8/site-packages/IPython/core/interactiveshell.py\", line 2045, in showtraceback\n",
      "    stb = value._render_traceback_()\n",
      "AttributeError: 'KeyboardInterrupt' object has no attribute '_render_traceback_'\n",
      "\n",
      "During handling of the above exception, another exception occurred:\n",
      "\n",
      "Traceback (most recent call last):\n",
      "  File \"/Applications/anaconda3/lib/python3.8/site-packages/IPython/core/interactiveshell.py\", line 3338, in run_ast_nodes\n",
      "    if (await self.run_code(code, result,  async_=asy)):\n",
      "  File \"/Applications/anaconda3/lib/python3.8/site-packages/IPython/core/interactiveshell.py\", line 3435, in run_code\n",
      "    self.showtraceback(running_compiled_code=True)\n",
      "  File \"/Applications/anaconda3/lib/python3.8/site-packages/IPython/core/interactiveshell.py\", line 2047, in showtraceback\n",
      "    stb = self.InteractiveTB.structured_traceback(etype,\n",
      "  File \"/Applications/anaconda3/lib/python3.8/site-packages/IPython/core/ultratb.py\", line 1436, in structured_traceback\n",
      "    return FormattedTB.structured_traceback(\n",
      "  File \"/Applications/anaconda3/lib/python3.8/site-packages/IPython/core/ultratb.py\", line 1336, in structured_traceback\n",
      "    return VerboseTB.structured_traceback(\n",
      "  File \"/Applications/anaconda3/lib/python3.8/site-packages/IPython/core/ultratb.py\", line 1193, in structured_traceback\n",
      "    formatted_exception = self.format_exception_as_a_whole(etype, evalue, etb, number_of_lines_of_context,\n",
      "  File \"/Applications/anaconda3/lib/python3.8/site-packages/IPython/core/ultratb.py\", line 1151, in format_exception_as_a_whole\n",
      "    last_unique, recursion_repeat = find_recursion(orig_etype, evalue, records)\n",
      "  File \"/Applications/anaconda3/lib/python3.8/site-packages/IPython/core/ultratb.py\", line 451, in find_recursion\n",
      "    return len(records), 0\n",
      "TypeError: object of type 'NoneType' has no len()\n",
      "\n",
      "During handling of the above exception, another exception occurred:\n",
      "\n",
      "Traceback (most recent call last):\n",
      "  File \"/Applications/anaconda3/lib/python3.8/site-packages/IPython/core/interactiveshell.py\", line 2045, in showtraceback\n",
      "    stb = value._render_traceback_()\n",
      "AttributeError: 'TypeError' object has no attribute '_render_traceback_'\n",
      "\n",
      "During handling of the above exception, another exception occurred:\n",
      "\n",
      "Traceback (most recent call last):\n",
      "  File \"/Applications/anaconda3/lib/python3.8/site-packages/IPython/core/ultratb.py\", line 1170, in get_records\n",
      "    return _fixed_getinnerframes(etb, number_of_lines_of_context, tb_offset)\n",
      "  File \"/Applications/anaconda3/lib/python3.8/site-packages/IPython/core/ultratb.py\", line 316, in wrapped\n",
      "    return f(*args, **kwargs)\n",
      "  File \"/Applications/anaconda3/lib/python3.8/site-packages/IPython/core/ultratb.py\", line 350, in _fixed_getinnerframes\n",
      "    records = fix_frame_records_filenames(inspect.getinnerframes(etb, context))\n",
      "  File \"/Applications/anaconda3/lib/python3.8/inspect.py\", line 1503, in getinnerframes\n",
      "    frameinfo = (tb.tb_frame,) + getframeinfo(tb, context)\n",
      "  File \"/Applications/anaconda3/lib/python3.8/inspect.py\", line 1461, in getframeinfo\n",
      "    filename = getsourcefile(frame) or getfile(frame)\n",
      "  File \"/Applications/anaconda3/lib/python3.8/inspect.py\", line 708, in getsourcefile\n",
      "    if getattr(getmodule(object, filename), '__loader__', None) is not None:\n",
      "  File \"/Applications/anaconda3/lib/python3.8/inspect.py\", line 737, in getmodule\n",
      "    file = getabsfile(object, _filename)\n",
      "  File \"/Applications/anaconda3/lib/python3.8/inspect.py\", line 721, in getabsfile\n",
      "    return os.path.normcase(os.path.abspath(_filename))\n",
      "  File \"/Applications/anaconda3/lib/python3.8/posixpath.py\", line 379, in abspath\n",
      "    cwd = os.getcwd()\n",
      "FileNotFoundError: [Errno 2] No such file or directory\n",
      "Traceback (most recent call last):\n",
      "  File \"/Applications/anaconda3/lib/python3.8/site-packages/IPython/core/interactiveshell.py\", line 3418, in run_code\n",
      "    exec(code_obj, self.user_global_ns, self.user_ns)\n",
      "  File \"<ipython-input-60-02dd82b79a8f>\", line 1, in <module>\n",
      "    car_matrix = cleanCalculateTravelTimeMatrixFromCoordVector(coordvector, \"driving\", mathiasAPI, False)\n",
      "  File \"<ipython-input-59-b25788eaccee>\", line 14, in cleanCalculateTravelTimeMatrixFromCoordVector\n",
      "    data = requests.get(url).json()\n",
      "  File \"/Applications/anaconda3/lib/python3.8/site-packages/requests/api.py\", line 76, in get\n",
      "    return request('get', url, params=params, **kwargs)\n",
      "  File \"/Applications/anaconda3/lib/python3.8/site-packages/requests/api.py\", line 61, in request\n",
      "    return session.request(method=method, url=url, **kwargs)\n",
      "  File \"/Applications/anaconda3/lib/python3.8/site-packages/requests/sessions.py\", line 530, in request\n",
      "    resp = self.send(prep, **send_kwargs)\n",
      "  File \"/Applications/anaconda3/lib/python3.8/site-packages/requests/sessions.py\", line 643, in send\n",
      "    r = adapter.send(request, **kwargs)\n",
      "  File \"/Applications/anaconda3/lib/python3.8/site-packages/requests/adapters.py\", line 439, in send\n",
      "    resp = conn.urlopen(\n",
      "  File \"/Applications/anaconda3/lib/python3.8/site-packages/urllib3/connectionpool.py\", line 670, in urlopen\n",
      "    httplib_response = self._make_request(\n",
      "  File \"/Applications/anaconda3/lib/python3.8/site-packages/urllib3/connectionpool.py\", line 426, in _make_request\n",
      "    six.raise_from(e, None)\n",
      "  File \"<string>\", line 3, in raise_from\n",
      "  File \"/Applications/anaconda3/lib/python3.8/site-packages/urllib3/connectionpool.py\", line 421, in _make_request\n",
      "    httplib_response = conn.getresponse()\n",
      "  File \"/Applications/anaconda3/lib/python3.8/http/client.py\", line 1347, in getresponse\n",
      "    response.begin()\n",
      "  File \"/Applications/anaconda3/lib/python3.8/http/client.py\", line 307, in begin\n",
      "    version, status, reason = self._read_status()\n",
      "  File \"/Applications/anaconda3/lib/python3.8/http/client.py\", line 268, in _read_status\n",
      "    line = str(self.fp.readline(_MAXLINE + 1), \"iso-8859-1\")\n",
      "  File \"/Applications/anaconda3/lib/python3.8/socket.py\", line 669, in readinto\n",
      "    return self._sock.recv_into(b)\n",
      "  File \"/Applications/anaconda3/lib/python3.8/ssl.py\", line 1241, in recv_into\n",
      "    return self.read(nbytes, buffer)\n",
      "  File \"/Applications/anaconda3/lib/python3.8/ssl.py\", line 1099, in read\n",
      "    return self._sslobj.read(len, buffer)\n",
      "KeyboardInterrupt\n",
      "\n",
      "During handling of the above exception, another exception occurred:\n",
      "\n",
      "Traceback (most recent call last):\n",
      "  File \"/Applications/anaconda3/lib/python3.8/site-packages/IPython/core/interactiveshell.py\", line 2045, in showtraceback\n",
      "    stb = value._render_traceback_()\n",
      "AttributeError: 'KeyboardInterrupt' object has no attribute '_render_traceback_'\n",
      "\n",
      "During handling of the above exception, another exception occurred:\n",
      "\n",
      "Traceback (most recent call last):\n",
      "  File \"/Applications/anaconda3/lib/python3.8/site-packages/IPython/core/interactiveshell.py\", line 3338, in run_ast_nodes\n",
      "    if (await self.run_code(code, result,  async_=asy)):\n",
      "  File \"/Applications/anaconda3/lib/python3.8/site-packages/IPython/core/interactiveshell.py\", line 3435, in run_code\n",
      "    self.showtraceback(running_compiled_code=True)\n",
      "  File \"/Applications/anaconda3/lib/python3.8/site-packages/IPython/core/interactiveshell.py\", line 2047, in showtraceback\n",
      "    stb = self.InteractiveTB.structured_traceback(etype,\n",
      "  File \"/Applications/anaconda3/lib/python3.8/site-packages/IPython/core/ultratb.py\", line 1436, in structured_traceback\n",
      "    return FormattedTB.structured_traceback(\n",
      "  File \"/Applications/anaconda3/lib/python3.8/site-packages/IPython/core/ultratb.py\", line 1336, in structured_traceback\n",
      "    return VerboseTB.structured_traceback(\n",
      "  File \"/Applications/anaconda3/lib/python3.8/site-packages/IPython/core/ultratb.py\", line 1193, in structured_traceback\n",
      "    formatted_exception = self.format_exception_as_a_whole(etype, evalue, etb, number_of_lines_of_context,\n",
      "  File \"/Applications/anaconda3/lib/python3.8/site-packages/IPython/core/ultratb.py\", line 1151, in format_exception_as_a_whole\n",
      "    last_unique, recursion_repeat = find_recursion(orig_etype, evalue, records)\n",
      "  File \"/Applications/anaconda3/lib/python3.8/site-packages/IPython/core/ultratb.py\", line 451, in find_recursion\n",
      "    return len(records), 0\n",
      "TypeError: object of type 'NoneType' has no len()\n",
      "\n",
      "During handling of the above exception, another exception occurred:\n",
      "\n",
      "Traceback (most recent call last):\n",
      "  File \"/Applications/anaconda3/lib/python3.8/site-packages/IPython/core/interactiveshell.py\", line 2045, in showtraceback\n",
      "    stb = value._render_traceback_()\n",
      "AttributeError: 'TypeError' object has no attribute '_render_traceback_'\n",
      "\n",
      "During handling of the above exception, another exception occurred:\n",
      "\n",
      "Traceback (most recent call last):\n",
      "  File \"/Applications/anaconda3/lib/python3.8/site-packages/IPython/core/interactiveshell.py\", line 2923, in _run_cell\n",
      "    return runner(coro)\n",
      "  File \"/Applications/anaconda3/lib/python3.8/site-packages/IPython/core/async_helpers.py\", line 68, in _pseudo_sync_runner\n",
      "    coro.send(None)\n",
      "  File \"/Applications/anaconda3/lib/python3.8/site-packages/IPython/core/interactiveshell.py\", line 3146, in run_cell_async\n",
      "    has_raised = await self.run_ast_nodes(code_ast.body, cell_name,\n",
      "  File \"/Applications/anaconda3/lib/python3.8/site-packages/IPython/core/interactiveshell.py\", line 3357, in run_ast_nodes\n",
      "    self.showtraceback()\n",
      "  File \"/Applications/anaconda3/lib/python3.8/site-packages/IPython/core/interactiveshell.py\", line 2047, in showtraceback\n",
      "    stb = self.InteractiveTB.structured_traceback(etype,\n",
      "  File \"/Applications/anaconda3/lib/python3.8/site-packages/IPython/core/ultratb.py\", line 1436, in structured_traceback\n",
      "    return FormattedTB.structured_traceback(\n",
      "  File \"/Applications/anaconda3/lib/python3.8/site-packages/IPython/core/ultratb.py\", line 1336, in structured_traceback\n",
      "    return VerboseTB.structured_traceback(\n",
      "  File \"/Applications/anaconda3/lib/python3.8/site-packages/IPython/core/ultratb.py\", line 1211, in structured_traceback\n",
      "    formatted_exceptions += self.format_exception_as_a_whole(etype, evalue, etb, lines_of_context,\n",
      "  File \"/Applications/anaconda3/lib/python3.8/site-packages/IPython/core/ultratb.py\", line 1151, in format_exception_as_a_whole\n",
      "    last_unique, recursion_repeat = find_recursion(orig_etype, evalue, records)\n",
      "  File \"/Applications/anaconda3/lib/python3.8/site-packages/IPython/core/ultratb.py\", line 451, in find_recursion\n",
      "    return len(records), 0\n",
      "TypeError: object of type 'NoneType' has no len()\n",
      "\n",
      "During handling of the above exception, another exception occurred:\n",
      "\n",
      "Traceback (most recent call last):\n",
      "  File \"/Applications/anaconda3/lib/python3.8/site-packages/IPython/core/interactiveshell.py\", line 2045, in showtraceback\n",
      "    stb = value._render_traceback_()\n",
      "AttributeError: 'TypeError' object has no attribute '_render_traceback_'\n",
      "\n",
      "During handling of the above exception, another exception occurred:\n",
      "\n",
      "Traceback (most recent call last):\n",
      "  File \"/Applications/anaconda3/lib/python3.8/site-packages/IPython/core/ultratb.py\", line 1170, in get_records\n",
      "    return _fixed_getinnerframes(etb, number_of_lines_of_context, tb_offset)\n",
      "  File \"/Applications/anaconda3/lib/python3.8/site-packages/IPython/core/ultratb.py\", line 316, in wrapped\n",
      "    return f(*args, **kwargs)\n",
      "  File \"/Applications/anaconda3/lib/python3.8/site-packages/IPython/core/ultratb.py\", line 350, in _fixed_getinnerframes\n",
      "    records = fix_frame_records_filenames(inspect.getinnerframes(etb, context))\n",
      "  File \"/Applications/anaconda3/lib/python3.8/inspect.py\", line 1503, in getinnerframes\n",
      "    frameinfo = (tb.tb_frame,) + getframeinfo(tb, context)\n",
      "  File \"/Applications/anaconda3/lib/python3.8/inspect.py\", line 1461, in getframeinfo\n",
      "    filename = getsourcefile(frame) or getfile(frame)\n",
      "  File \"/Applications/anaconda3/lib/python3.8/inspect.py\", line 708, in getsourcefile\n",
      "    if getattr(getmodule(object, filename), '__loader__', None) is not None:\n",
      "  File \"/Applications/anaconda3/lib/python3.8/inspect.py\", line 737, in getmodule\n",
      "    file = getabsfile(object, _filename)\n",
      "  File \"/Applications/anaconda3/lib/python3.8/inspect.py\", line 721, in getabsfile\n",
      "    return os.path.normcase(os.path.abspath(_filename))\n",
      "  File \"/Applications/anaconda3/lib/python3.8/posixpath.py\", line 379, in abspath\n",
      "    cwd = os.getcwd()\n",
      "FileNotFoundError: [Errno 2] No such file or directory\n"
     ]
    }
   ],
   "source": [
    "car_matrix = cleanCalculateTravelTimeMatrixFromCoordVector(coordvector, \"driving\", mathiasAPI, False)"
   ]
  },
  {
   "cell_type": "code",
   "execution_count": null,
   "metadata": {},
   "outputs": [
    {
     "name": "stderr",
     "output_type": "stream",
     "text": [
      "ERROR:root:Internal Python error in the inspect module.\n",
      "Below is the traceback from this internal error.\n",
      "\n",
      "ERROR:root:Internal Python error in the inspect module.\n",
      "Below is the traceback from this internal error.\n",
      "\n",
      "ERROR:root:Internal Python error in the inspect module.\n",
      "Below is the traceback from this internal error.\n",
      "\n"
     ]
    },
    {
     "name": "stdout",
     "output_type": "stream",
     "text": [
      "ERROR! Session/line number was not unique in database. History logging moved to new session 142\n",
      "Traceback (most recent call last):\n",
      "  File \"/Applications/anaconda3/lib/python3.8/site-packages/IPython/core/interactiveshell.py\", line 3418, in run_code\n",
      "    exec(code_obj, self.user_global_ns, self.user_ns)\n",
      "  File \"<ipython-input-60-28a65da98afb>\", line 1, in <module>\n",
      "    car_matrix\n",
      "NameError: name 'car_matrix' is not defined\n",
      "\n",
      "During handling of the above exception, another exception occurred:\n",
      "\n",
      "Traceback (most recent call last):\n",
      "  File \"/Applications/anaconda3/lib/python3.8/site-packages/IPython/core/interactiveshell.py\", line 2045, in showtraceback\n",
      "    stb = value._render_traceback_()\n",
      "AttributeError: 'NameError' object has no attribute '_render_traceback_'\n",
      "\n",
      "During handling of the above exception, another exception occurred:\n",
      "\n",
      "Traceback (most recent call last):\n",
      "  File \"/Applications/anaconda3/lib/python3.8/site-packages/IPython/core/ultratb.py\", line 1170, in get_records\n",
      "    return _fixed_getinnerframes(etb, number_of_lines_of_context, tb_offset)\n",
      "  File \"/Applications/anaconda3/lib/python3.8/site-packages/IPython/core/ultratb.py\", line 316, in wrapped\n",
      "    return f(*args, **kwargs)\n",
      "  File \"/Applications/anaconda3/lib/python3.8/site-packages/IPython/core/ultratb.py\", line 350, in _fixed_getinnerframes\n",
      "    records = fix_frame_records_filenames(inspect.getinnerframes(etb, context))\n",
      "  File \"/Applications/anaconda3/lib/python3.8/inspect.py\", line 1503, in getinnerframes\n",
      "    frameinfo = (tb.tb_frame,) + getframeinfo(tb, context)\n",
      "  File \"/Applications/anaconda3/lib/python3.8/inspect.py\", line 1461, in getframeinfo\n",
      "    filename = getsourcefile(frame) or getfile(frame)\n",
      "  File \"/Applications/anaconda3/lib/python3.8/inspect.py\", line 708, in getsourcefile\n",
      "    if getattr(getmodule(object, filename), '__loader__', None) is not None:\n",
      "  File \"/Applications/anaconda3/lib/python3.8/inspect.py\", line 737, in getmodule\n",
      "    file = getabsfile(object, _filename)\n",
      "  File \"/Applications/anaconda3/lib/python3.8/inspect.py\", line 721, in getabsfile\n",
      "    return os.path.normcase(os.path.abspath(_filename))\n",
      "  File \"/Applications/anaconda3/lib/python3.8/posixpath.py\", line 379, in abspath\n",
      "    cwd = os.getcwd()\n",
      "FileNotFoundError: [Errno 2] No such file or directory\n",
      "Traceback (most recent call last):\n",
      "  File \"/Applications/anaconda3/lib/python3.8/site-packages/IPython/core/interactiveshell.py\", line 3418, in run_code\n",
      "    exec(code_obj, self.user_global_ns, self.user_ns)\n",
      "  File \"<ipython-input-60-28a65da98afb>\", line 1, in <module>\n",
      "    car_matrix\n",
      "NameError: name 'car_matrix' is not defined\n",
      "\n",
      "During handling of the above exception, another exception occurred:\n",
      "\n",
      "Traceback (most recent call last):\n",
      "  File \"/Applications/anaconda3/lib/python3.8/site-packages/IPython/core/interactiveshell.py\", line 2045, in showtraceback\n",
      "    stb = value._render_traceback_()\n",
      "AttributeError: 'NameError' object has no attribute '_render_traceback_'\n",
      "\n",
      "During handling of the above exception, another exception occurred:\n",
      "\n",
      "Traceback (most recent call last):\n",
      "  File \"/Applications/anaconda3/lib/python3.8/site-packages/IPython/core/interactiveshell.py\", line 3338, in run_ast_nodes\n",
      "    if (await self.run_code(code, result,  async_=asy)):\n",
      "  File \"/Applications/anaconda3/lib/python3.8/site-packages/IPython/core/interactiveshell.py\", line 3435, in run_code\n",
      "    self.showtraceback(running_compiled_code=True)\n",
      "  File \"/Applications/anaconda3/lib/python3.8/site-packages/IPython/core/interactiveshell.py\", line 2047, in showtraceback\n",
      "    stb = self.InteractiveTB.structured_traceback(etype,\n",
      "  File \"/Applications/anaconda3/lib/python3.8/site-packages/IPython/core/ultratb.py\", line 1436, in structured_traceback\n",
      "    return FormattedTB.structured_traceback(\n",
      "  File \"/Applications/anaconda3/lib/python3.8/site-packages/IPython/core/ultratb.py\", line 1336, in structured_traceback\n",
      "    return VerboseTB.structured_traceback(\n",
      "  File \"/Applications/anaconda3/lib/python3.8/site-packages/IPython/core/ultratb.py\", line 1193, in structured_traceback\n",
      "    formatted_exception = self.format_exception_as_a_whole(etype, evalue, etb, number_of_lines_of_context,\n",
      "  File \"/Applications/anaconda3/lib/python3.8/site-packages/IPython/core/ultratb.py\", line 1151, in format_exception_as_a_whole\n",
      "    last_unique, recursion_repeat = find_recursion(orig_etype, evalue, records)\n",
      "  File \"/Applications/anaconda3/lib/python3.8/site-packages/IPython/core/ultratb.py\", line 451, in find_recursion\n",
      "    return len(records), 0\n",
      "TypeError: object of type 'NoneType' has no len()\n",
      "\n",
      "During handling of the above exception, another exception occurred:\n",
      "\n",
      "Traceback (most recent call last):\n",
      "  File \"/Applications/anaconda3/lib/python3.8/site-packages/IPython/core/interactiveshell.py\", line 2045, in showtraceback\n",
      "    stb = value._render_traceback_()\n",
      "AttributeError: 'TypeError' object has no attribute '_render_traceback_'\n",
      "\n",
      "During handling of the above exception, another exception occurred:\n",
      "\n",
      "Traceback (most recent call last):\n",
      "  File \"/Applications/anaconda3/lib/python3.8/site-packages/IPython/core/ultratb.py\", line 1170, in get_records\n",
      "    return _fixed_getinnerframes(etb, number_of_lines_of_context, tb_offset)\n",
      "  File \"/Applications/anaconda3/lib/python3.8/site-packages/IPython/core/ultratb.py\", line 316, in wrapped\n",
      "    return f(*args, **kwargs)\n",
      "  File \"/Applications/anaconda3/lib/python3.8/site-packages/IPython/core/ultratb.py\", line 350, in _fixed_getinnerframes\n",
      "    records = fix_frame_records_filenames(inspect.getinnerframes(etb, context))\n",
      "  File \"/Applications/anaconda3/lib/python3.8/inspect.py\", line 1503, in getinnerframes\n",
      "    frameinfo = (tb.tb_frame,) + getframeinfo(tb, context)\n",
      "  File \"/Applications/anaconda3/lib/python3.8/inspect.py\", line 1461, in getframeinfo\n",
      "    filename = getsourcefile(frame) or getfile(frame)\n",
      "  File \"/Applications/anaconda3/lib/python3.8/inspect.py\", line 708, in getsourcefile\n",
      "    if getattr(getmodule(object, filename), '__loader__', None) is not None:\n",
      "  File \"/Applications/anaconda3/lib/python3.8/inspect.py\", line 737, in getmodule\n",
      "    file = getabsfile(object, _filename)\n",
      "  File \"/Applications/anaconda3/lib/python3.8/inspect.py\", line 721, in getabsfile\n",
      "    return os.path.normcase(os.path.abspath(_filename))\n",
      "  File \"/Applications/anaconda3/lib/python3.8/posixpath.py\", line 379, in abspath\n",
      "    cwd = os.getcwd()\n",
      "FileNotFoundError: [Errno 2] No such file or directory\n",
      "Traceback (most recent call last):\n",
      "  File \"/Applications/anaconda3/lib/python3.8/site-packages/IPython/core/interactiveshell.py\", line 3418, in run_code\n",
      "    exec(code_obj, self.user_global_ns, self.user_ns)\n",
      "  File \"<ipython-input-60-28a65da98afb>\", line 1, in <module>\n",
      "    car_matrix\n",
      "NameError: name 'car_matrix' is not defined\n",
      "\n",
      "During handling of the above exception, another exception occurred:\n",
      "\n",
      "Traceback (most recent call last):\n",
      "  File \"/Applications/anaconda3/lib/python3.8/site-packages/IPython/core/interactiveshell.py\", line 2045, in showtraceback\n",
      "    stb = value._render_traceback_()\n",
      "AttributeError: 'NameError' object has no attribute '_render_traceback_'\n",
      "\n",
      "During handling of the above exception, another exception occurred:\n",
      "\n",
      "Traceback (most recent call last):\n",
      "  File \"/Applications/anaconda3/lib/python3.8/site-packages/IPython/core/interactiveshell.py\", line 3338, in run_ast_nodes\n",
      "    if (await self.run_code(code, result,  async_=asy)):\n",
      "  File \"/Applications/anaconda3/lib/python3.8/site-packages/IPython/core/interactiveshell.py\", line 3435, in run_code\n",
      "    self.showtraceback(running_compiled_code=True)\n",
      "  File \"/Applications/anaconda3/lib/python3.8/site-packages/IPython/core/interactiveshell.py\", line 2047, in showtraceback\n",
      "    stb = self.InteractiveTB.structured_traceback(etype,\n",
      "  File \"/Applications/anaconda3/lib/python3.8/site-packages/IPython/core/ultratb.py\", line 1436, in structured_traceback\n",
      "    return FormattedTB.structured_traceback(\n",
      "  File \"/Applications/anaconda3/lib/python3.8/site-packages/IPython/core/ultratb.py\", line 1336, in structured_traceback\n",
      "    return VerboseTB.structured_traceback(\n",
      "  File \"/Applications/anaconda3/lib/python3.8/site-packages/IPython/core/ultratb.py\", line 1193, in structured_traceback\n",
      "    formatted_exception = self.format_exception_as_a_whole(etype, evalue, etb, number_of_lines_of_context,\n",
      "  File \"/Applications/anaconda3/lib/python3.8/site-packages/IPython/core/ultratb.py\", line 1151, in format_exception_as_a_whole\n",
      "    last_unique, recursion_repeat = find_recursion(orig_etype, evalue, records)\n",
      "  File \"/Applications/anaconda3/lib/python3.8/site-packages/IPython/core/ultratb.py\", line 451, in find_recursion\n",
      "    return len(records), 0\n",
      "TypeError: object of type 'NoneType' has no len()\n",
      "\n",
      "During handling of the above exception, another exception occurred:\n",
      "\n",
      "Traceback (most recent call last):\n",
      "  File \"/Applications/anaconda3/lib/python3.8/site-packages/IPython/core/interactiveshell.py\", line 2045, in showtraceback\n",
      "    stb = value._render_traceback_()\n",
      "AttributeError: 'TypeError' object has no attribute '_render_traceback_'\n",
      "\n",
      "During handling of the above exception, another exception occurred:\n",
      "\n",
      "Traceback (most recent call last):\n",
      "  File \"/Applications/anaconda3/lib/python3.8/site-packages/IPython/core/interactiveshell.py\", line 2923, in _run_cell\n",
      "    return runner(coro)\n",
      "  File \"/Applications/anaconda3/lib/python3.8/site-packages/IPython/core/async_helpers.py\", line 68, in _pseudo_sync_runner\n",
      "    coro.send(None)\n",
      "  File \"/Applications/anaconda3/lib/python3.8/site-packages/IPython/core/interactiveshell.py\", line 3146, in run_cell_async\n",
      "    has_raised = await self.run_ast_nodes(code_ast.body, cell_name,\n",
      "  File \"/Applications/anaconda3/lib/python3.8/site-packages/IPython/core/interactiveshell.py\", line 3357, in run_ast_nodes\n",
      "    self.showtraceback()\n",
      "  File \"/Applications/anaconda3/lib/python3.8/site-packages/IPython/core/interactiveshell.py\", line 2047, in showtraceback\n",
      "    stb = self.InteractiveTB.structured_traceback(etype,\n",
      "  File \"/Applications/anaconda3/lib/python3.8/site-packages/IPython/core/ultratb.py\", line 1436, in structured_traceback\n",
      "    return FormattedTB.structured_traceback(\n",
      "  File \"/Applications/anaconda3/lib/python3.8/site-packages/IPython/core/ultratb.py\", line 1336, in structured_traceback\n",
      "    return VerboseTB.structured_traceback(\n",
      "  File \"/Applications/anaconda3/lib/python3.8/site-packages/IPython/core/ultratb.py\", line 1211, in structured_traceback\n",
      "    formatted_exceptions += self.format_exception_as_a_whole(etype, evalue, etb, lines_of_context,\n",
      "  File \"/Applications/anaconda3/lib/python3.8/site-packages/IPython/core/ultratb.py\", line 1151, in format_exception_as_a_whole\n",
      "    last_unique, recursion_repeat = find_recursion(orig_etype, evalue, records)\n",
      "  File \"/Applications/anaconda3/lib/python3.8/site-packages/IPython/core/ultratb.py\", line 451, in find_recursion\n",
      "    return len(records), 0\n",
      "TypeError: object of type 'NoneType' has no len()\n",
      "\n",
      "During handling of the above exception, another exception occurred:\n",
      "\n",
      "Traceback (most recent call last):\n",
      "  File \"/Applications/anaconda3/lib/python3.8/site-packages/IPython/core/interactiveshell.py\", line 2045, in showtraceback\n",
      "    stb = value._render_traceback_()\n",
      "AttributeError: 'TypeError' object has no attribute '_render_traceback_'\n",
      "\n",
      "During handling of the above exception, another exception occurred:\n",
      "\n",
      "Traceback (most recent call last):\n",
      "  File \"/Applications/anaconda3/lib/python3.8/site-packages/IPython/core/ultratb.py\", line 1170, in get_records\n",
      "    return _fixed_getinnerframes(etb, number_of_lines_of_context, tb_offset)\n",
      "  File \"/Applications/anaconda3/lib/python3.8/site-packages/IPython/core/ultratb.py\", line 316, in wrapped\n",
      "    return f(*args, **kwargs)\n",
      "  File \"/Applications/anaconda3/lib/python3.8/site-packages/IPython/core/ultratb.py\", line 350, in _fixed_getinnerframes\n",
      "    records = fix_frame_records_filenames(inspect.getinnerframes(etb, context))\n",
      "  File \"/Applications/anaconda3/lib/python3.8/inspect.py\", line 1503, in getinnerframes\n",
      "    frameinfo = (tb.tb_frame,) + getframeinfo(tb, context)\n",
      "  File \"/Applications/anaconda3/lib/python3.8/inspect.py\", line 1461, in getframeinfo\n",
      "    filename = getsourcefile(frame) or getfile(frame)\n",
      "  File \"/Applications/anaconda3/lib/python3.8/inspect.py\", line 708, in getsourcefile\n",
      "    if getattr(getmodule(object, filename), '__loader__', None) is not None:\n",
      "  File \"/Applications/anaconda3/lib/python3.8/inspect.py\", line 737, in getmodule\n",
      "    file = getabsfile(object, _filename)\n",
      "  File \"/Applications/anaconda3/lib/python3.8/inspect.py\", line 721, in getabsfile\n",
      "    return os.path.normcase(os.path.abspath(_filename))\n",
      "  File \"/Applications/anaconda3/lib/python3.8/posixpath.py\", line 379, in abspath\n",
      "    cwd = os.getcwd()\n",
      "FileNotFoundError: [Errno 2] No such file or directory\n"
     ]
    }
   ],
   "source": [
    "car_matrix"
   ]
  },
  {
   "cell_type": "code",
   "execution_count": null,
   "metadata": {},
   "outputs": [],
   "source": []
  }
 ],
 "metadata": {
  "kernelspec": {
   "display_name": "Python 3",
   "language": "python",
   "name": "python3"
  },
  "language_info": {
   "codemirror_mode": {
    "name": "ipython",
    "version": 3
   },
   "file_extension": ".py",
   "mimetype": "text/x-python",
   "name": "python",
   "nbconvert_exporter": "python",
   "pygments_lexer": "ipython3",
   "version": "3.8.5"
  }
 },
 "nbformat": 4,
 "nbformat_minor": 4
}
